Workbook
Name lista: _xludf.REPLACE(_xludf.GET.WORKBOOK(1),1,_xludf.FIND("]",_xludf.GET.WORKBOOK(1)),"")
Name lista: _xludf.REPLACE(_xludf.GET.WORKBOOK(1),1,_xludf.FIND("]",_xludf.GET.WORKBOOK(1)),"")
Name lista: _xludf.REPLACE(_xludf.GET.WORKBOOK(1),1,_xludf.FIND("]",_xludf.GET.WORKBOOK(1)),"")
Name lista: _xludf.REPLACE(_xludf.GET.WORKBOOK(1),1,_xludf.FIND("]",_xludf.GET.WORKBOOK(1)),"")
Name lista: _xludf.REPLACE(_xludf.GET.WORKBOOK(1),1,_xludf.FIND("]",_xludf.GET.WORKBOOK(1)),"")
Name lista: _xludf.REPLACE(_xludf.GET.WORKBOOK(1),1,_xludf.FIND("]",_xludf.GET.WORKBOOK(1)),"")
Name lista: _xludf.REPLACE(_xludf.GET.WORKBOOK(1),1,_xludf.FIND("]",_xludf.GET.WORKBOOK(1)),"")
Name lista: _xludf.REPLACE(_xludf.GET.WORKBOOK(1),1,_xludf.FIND("]",_xludf.GET.WORKBOOK(1)),"")
Name lista: _xludf.REPLACE(_xludf.GET.WORKBOOK(1),1,_xludf.FIND("]",_xludf.GET.WORKBOOK(1)),"")
Name lista: _xludf.REPLACE(_xludf.GET.WORKBOOK(1),1,_xludf.FIND("]",_xludf.GET.WORKBOOK(1)),"")
Name lista: _xludf.REPLACE(_xludf.GET.WORKBOOK(1),1,_xludf.FIND("]",_xludf.GET.WORKBOOK(1)),"")
Name lista: _xludf.REPLACE(_xludf.GET.WORKBOOK(1),1,_xludf.FIND("]",_xludf.GET.WORKBOOK(1)),"")
Name lista: _xludf.REPLACE(_xludf.GET.WORKBOOK(1),1,_xludf.FIND("]",_xludf.GET.WORKBOOK(1)),"")
Name lista: _xludf.REPLACE(_xludf.GET.WORKBOOK(1),1,_xludf.FIND("]",_xludf.GET.WORKBOOK(1)),"")
Name lista: _xludf.REPLACE(_xludf.GET.WORKBOOK(1),1,_xludf.FIND("]",_xludf.GET.WORKBOOK(1)),"")
Name lista: _xludf.REPLACE(_xludf.GET.WORKBOOK(1),1,_xludf.FIND("]",_xludf.GET.WORKBOOK(1)),"")
Name lista: _xludf.REPLACE(_xludf.GET.WORKBOOK(1),1,_xludf.FIND("]",_xludf.GET.WORKBOOK(1)),"")

Sheet Brownie 14 cm
B1: Ingrediente | C1: Gramos | D1: Precio | E1: Total Recetas | F1: Cantidad de Recetas: | G1: 1
B2: Manteca | C2: 60 | D2: =C2*'Valores y Totales'!C2 -> 660 | E2: =G$1*C2 -> 60
B3: Harina 0000 | C3: 0 | D3: =C3*'Valores y Totales'!C3 -> 0 | E3: =G$1*C3 -> 0
B4: Azucar Impalpable | C4: 0 | D4: =C4*'Valores y Totales'!C4 -> 0 | E4: =G$1*C4 -> 0
B5: Cacao | C5: 0 | D5: =C5*'Valores y Totales'!C5 -> 0 | E5: =G$1*C5 -> 0
B6: Huevo (unidad) | C6: 0 | D6: =C6*'Valores y Totales'!B6 -> 0 | E6: =G$1*C6 -> 0
B7: Azucar Común | C7: 0 | D7: =C7*'Valores y Totales'!C7 -> 0 | E7: =G$1*C7 -> 0
B8: Maizena | C8: 0 | D8: =C8*'Valores y Totales'!C8 -> 0 | E8: =G$1*C8 -> 0
B9: Chocolate Taza | C9: 150 | D9: =C9*'Valores y Totales'!C9 -> 3900 | E9: =G$1*C9 -> 150
B10: Nueces | C10: 0 | D10: =C10*'Valores y Totales'!C10 -> 0 | E10: =G$1*C10 -> 0
B11: Dulce de Leche | C11: 400 | D11: =C11*'Valores y Totales'!C11 -> 2000 | E11: =G$1*C11 -> 400
B12: Crema | C12: 120 | D12: =C12*'Valores y Totales'!C12 -> 1200 | E12: =G$1*C12 -> 120
B13: Harina Leudante | C13: 0 | D13: =C13*'Valores y Totales'!C13 -> 0 | E13: =G$1*C13 -> 0
B14: Limon | C14: 0 | D14: =C14*'Valores y Totales'!C14 -> 0 | E14: =G$1*C14 -> 0
B15: Bicarbonato | C15: 0 | D15: =C15*'Valores y Totales'!C15 -> 0 | E15: =G$1*C15 -> 0
B16: Polveo Hornear | C16: 0 | D16: =C16*'Valores y Totales'!C16 -> 0 | E16: =G$1*C16 -> 0
B17: Leche | C17: 0 | D17: =C17*'Valores y Totales'!C17 -> 0 | E17: =G$1*C17 -> 0
B18: Conac | C18: 30 | D18: =C18*'Valores y Totales'!C18 -> 400 | E18: =G$1*C18 -> 30
... B26: Chocochips | C26: 0 | D26: =C26*'Valores y Totales'!C26 -> 0 | E26: =G$1*C26 -> 0
C28: Una Receta | D28: Por Cantidad de Recetas
B29: Cantidad de Masitas | C29: 1 | D29: =C29*G$1 -> 1
B30: Costo Receta | C30: =SUM(D2:D26) -> 8160 | D30: =C30*G$1 -> 8160
B31: Costo Docena | C31: =C30/C29*12 -> 97920 | D31: =C31 -> 97920
B32: Costo Individual | C32: =C30/C29 -> 8160 | D32: =C32 -> 8160

Sheet Tarta de Coco placa 20x30
B1: Ingrediente | C1: Gramos | D1: Precio | E1: Total Recetas | F1: Cantidad de Recetas: | G1: 1
B2: Manteca | C2: 155 | D2: =C2*'Valores y Totales'!C2 -> 1705 | E2: =G$1*C2 -> 155
B3: Harina 0000 | C3: 250 | D3: =C3*'Valores y Totales'!C3 -> 275 | E3: =G$1*C3 -> 250
B4: Azucar Impalpable | C4: 150 | D4: =C4*'Valores y Totales'!C4 -> 225 | E4: =G$1*C4 -> 150
B5: Cacao | C5: 0 | D5: =C5*'Valores y Totales'!C5 -> 0 | E5: =G$1*C5 -> 0
B6: Huevo (unidad) | C6: 3 | D6: =C6*'Valores y Totales'!B6 -> 630 | E6: =G$1*C6 -> 3
B7: Azucar Común | C7: 75 | D7: =C7*'Valores y Totales'!C7 -> 105 | E7: =G$1*C7 -> 75
B8: Maizena | C8: 0 | D8: =C8*'Valores y Totales'!C8 -> 0 | E8: =G$1*C8 -> 0
B9: Chocolate Taza | C9: 0 | D9: =C9*'Valores y Totales'!C9 -> 0 | E9: =G$1*C9 -> 0
B10: Nueces | C10: 0 | D10: =C10*'Valores y Totales'!C10 -> 0 | E10: =G$1*C10 -> 0
B11: Dulce de Leche | C11: 700 | D11: =C11*'Valores y Totales'!C11 -> 3500 | E11: =G$1*C11 -> 700
B12: Crema | C12: 0 | D12: =C12*'Valores y Totales'!C12 -> 0 | E12: =G$1*C12 -> 0
B13: Harina Leudante | C13: 0 | D13: =C13*'Valores y Totales'!C13 -> 0 | E13: =G$1*C13 -> 0
B14: Limon | C14: 1 | D14: =C14*'Valores y Totales'!C14 -> 500 | E14: =G$1*C14 -> 1
B15: Bicarbonato | C15: 0 | D15: =C15*'Valores y Totales'!C15 -> 0 | E15: =G$1*C15 -> 0
B16: Polveo Hornear | C16: 7 | D16: =C16*'Valores y Totales'!C16 -> 28 | E16: =G$1*C16 -> 7
B17: Leche | C17: 0 | D17: =C17*'Valores y Totales'!C17 -> 0 | E17: =G$1*C17 -> 0
B18: Conac | C18: 0 | D18: =C18*'Valores y Totales'!C18 -> 0 | E18: =G$1*C18 -> 0
... B24: Pasas | C24: 0 | D24: =C24*'Valores y Totales'!C24 -> 0 | E24: =G$1*C24 -> 0
B25: Coco | C25: 150 | D25: =C25*'Valores y Totales'!C44 -> 1800 | E25: =G$1*C25 -> 150
B26: Dulce de Membrillo | C26: 0 | D26: =C26*'Valores y Totales'!C45 -> 0 | E26: =G$1*C26 -> 0
B27: Chocochips | C27: 0 | D27: =C27*'Valores y Totales'!C26 -> 0 | E27: =G$1*C27 -> 0
C29: Una Receta | D29: Por Cantidad de Recetas
B30: Cantidad de Masitas | C30: 30 | D30: 70
B31: Costo Receta | C31: =SUM(D2:D27) -> 8768 | D31: =C31*G$1 -> 8768
B32: Costo por unidad | C32: =C31/C30 -> 292.26667 | D32: =C32 -> 292.26667
B33: Costo Individual | C33: =C31/C30 -> 292.26667 | D33: =C33 -> 292.26667

Sheet Minifrola-DDL-Coco
B1: Ingrediente | C1: Gramos | D1: Precio | E1: Total Recetas | F1: Cantidad de Recetas: | G1: 1
B2: Manteca | C2: 310 | D2: =C2*'Valores y Totales'!C2 -> 3410 | E2: =G$1*C2 -> 310
B3: Harina 0000 | C3: 500 | D3: =C3*'Valores y Totales'!C3 -> 550 | E3: =G$1*C3 -> 500
B4: Azucar Impalpable | C4: 150 | D4: =C4*'Valores y Totales'!C4 -> 225 | E4: =G$1*C4 -> 150
B5: Cacao | C5: 0 | D5: =C5*'Valores y Totales'!C5 -> 0 | E5: =G$1*C5 -> 0
B6: Huevo (unidad) | C6: 6 | D6: =C6*'Valores y Totales'!B6 -> 1260 | E6: =G$1*C6 -> 6
B7: Azucar Común | C7: 150 | D7: =C7*'Valores y Totales'!C7 -> 210 | E7: =G$1*C7 -> 150
B8: Maizena | C8: 0 | D8: =C8*'Valores y Totales'!C8 -> 0 | E8: =G$1*C8 -> 0
B9: Chocolate Taza | C9: 0 | D9: =C9*'Valores y Totales'!C9 -> 0 | E9: =G$1*C9 -> 0
B10: Nueces | C10: 0 | D10: =C10*'Valores y Totales'!C10 -> 0 | E10: =G$1*C10 -> 0
B11: Dulce de Leche | C11: 1200 | D11: =C11*'Valores y Totales'!C11 -> 6000 | E11: =G$1*C11 -> 1200
B12: Crema | C12: 0 | D12: =C12*'Valores y Totales'!C12 -> 0 | E12: =G$1*C12 -> 0
B13: Harina Leudante | C13: 0 | D13: =C13*'Valores y Totales'!C13 -> 0 | E13: =G$1*C13 -> 0
B14: Limon | C14: 1 | D14: =C14*'Valores y Totales'!C14 -> 500 | E14: =G$1*C14 -> 1
B15: Bicarbonato | C15: 0 | D15: =C15*'Valores y Totales'!C15 -> 0 | E15: =G$1*C15 -> 0
B16: Polveo Hornear | C16: 15 | D16: =C16*'Valores y Totales'!C16 -> 60 | E16: =G$1*C16 -> 15
B17: Leche | C17: 0 | D17: =C17*'Valores y Totales'!C17 -> 0 | E17: =G$1*C17 -> 0
B18: Conac | C18: 0 | D18: =C18*'Valores y Totales'!C18 -> 0 | E18: =G$1*C18 -> 0
... B24: Pasas | C24: 0 | D24: =C24*'Valores y Totales'!C24 -> 0 | E24: =G$1*C24 -> 0
B25: Coco | C25: 300 | D25: =C25*'Valores y Totales'!C44 -> 3600 | E25: =G$1*C25 -> 300
B26: Dulce de Membrillo | C26: 0 | D26: =C26*'Valores y Totales'!C45 -> 0 | E26: =G$1*C26 -> 0
B27: Chocochips | C27: 0 | D27: =C27*'Valores y Totales'!C26 -> 0 | E27: =G$1*C27 -> 0
C29: Una Receta | D29: Por Cantidad de Recetas
B30: Cantidad de Masitas | C30: 15 | D30: =C30*G$1 -> 15 | E30: de 8 cm
B31: Costo Receta | C31: =SUM(D2:D27) -> 15815 | D31: =C31*G$1 -> 15815
B32: Costo por unidad | C32: =C31/C30 -> 1054.3333 | D32: =C32 -> 1054.3333
B33: Costo Individual | C33: =C31/C30 -> 1054.3333 | D33: =C33 -> 1054.3333

Sheet Minifrola-Manzana
B1: Ingrediente | C1: Gramos | D1: Precio | E1: Total Recetas | F1: Cantidad de Recetas: | G1: 1
B2: Manteca | C2: 350 | D2: =C2*'Valores y Totales'!C2 -> 3850 | E2: =G$1*C2 -> 350
B3: Harina 0000 | C3: 500 | D3: =C3*'Valores y Totales'!C3 -> 550 | E3: =G$1*C3 -> 500
B4: Azucar Impalpable | C4: 150 | D4: =C4*'Valores y Totales'!C4 -> 225 | E4: =G$1*C4 -> 150
B5: Cacao | C5: 0 | D5: =C5*'Valores y Totales'!C5 -> 0 | E5: =G$1*C5 -> 0
B6: Huevo (unidad) | C6: 2 | D6: =C6*'Valores y Totales'!B6 -> 420 | E6: =G$1*C6 -> 2
B7: Azucar Común | C7: 160 | D7: =C7*'Valores y Totales'!C7 -> 224 | E7: =G$1*C7 -> 160
B8: Maizena | C8: 0 | D8: =C8*'Valores y Totales'!C8 -> 0 | E8: =G$1*C8 -> 0
B9: Chocolate Taza | C9: 0 | D9: =C9*'Valores y Totales'!C9 -> 0 | E9: =G$1*C9 -> 0
B10: Nueces | C10: 0 | D10: =C10*'Valores y Totales'!C10 -> 0 | E10: =G$1*C10 -> 0
B11: Dulce de Leche | C11: 0 | D11: =C11*'Valores y Totales'!C11 -> 0 | E11: =G$1*C11 -> 0
B12: Crema | C12: 0 | D12: =C12*'Valores y Totales'!C12 -> 0 | E12: =G$1*C12 -> 0
B13: Harina Leudante | C13: 0 | D13: =C13*'Valores y Totales'!C13 -> 0 | E13: =G$1*C13 -> 0
B14: Limon | C14: 1 | D14: =C14*'Valores y Totales'!C14 -> 500 | E14: =G$1*C14 -> 1
B15: Bicarbonato | C15: 0 | D15: =C15*'Valores y Totales'!C15 -> 0 | E15: =G$1*C15 -> 0
B16: Polveo Hornear | C16: 15 | D16: =C16*'Valores y Totales'!C16 -> 60 | E16: =G$1*C16 -> 15
B17: Leche | C17: 0 | D17: =C17*'Valores y Totales'!C17 -> 0 | E17: =G$1*C17 -> 0
B18: Conac | C18: 0 | D18: =C18*'Valores y Totales'!C18 -> 0 | E18: =G$1*C18 -> 0
... B25: Yogur | C25: 0 | D25: =C25*'Valores y Totales'!C25 -> 0 | E25: =G$1*C25 -> 0
B26: Manzana | C26: 10 | D26: =C26*'Valores y Totales'!C49 -> 6000 | E26: =G$1*C26 -> 10
B27: Chocochips | C27: 0 | D27: =C27*'Valores y Totales'!C26 -> 0 | E27: =G$1*C27 -> 0
C29: Una Receta | D29: Por Cantidad de Recetas
B30: Cantidad de Masitas | C30: 15 | D30: =C30*G$1 -> 15 | E30: de 8 cm
B31: Costo Receta | C31: =SUM(D2:D27) -> 11829 | D31: =C31*G$1 -> 11829
B32: Costo por unidad | C32: =C31/C30 -> 788.6 | D32: =C32 -> 788.6
B33: Costo Individual | C33: =C31/C30 -> 788.6 | D33: =C33 -> 788.6

Sheet Minifrola-DDL
B1: Ingrediente | C1: Gramos | D1: Precio | E1: Total Recetas | F1: Cantidad de Recetas: | G1: 1
B2: Manteca | C2: 250 | D2: =C2*'Valores y Totales'!C2 -> 2750 | E2: =G$1*C2 -> 250
B3: Harina 0000 | C3: 500 | D3: =C3*'Valores y Totales'!C3 -> 550 | E3: =G$1*C3 -> 500
B4: Azucar Impalpable | C4: 150 | D4: =C4*'Valores y Totales'!C4 -> 225 | E4: =G$1*C4 -> 150
B5: Cacao | C5: 0 | D5: =C5*'Valores y Totales'!C5 -> 0 | E5: =G$1*C5 -> 0
B6: Huevo (unidad) | C6: 2 | D6: =C6*'Valores y Totales'!B6 -> 420 | E6: =G$1*C6 -> 2
B7: Azucar Común | C7: 0 | D7: =C7*'Valores y Totales'!C7 -> 0 | E7: =G$1*C7 -> 0
B8: Maizena | C8: 0 | D8: =C8*'Valores y Totales'!C8 -> 0 | E8: =G$1*C8 -> 0
B9: Chocolate Taza | C9: 0 | D9: =C9*'Valores y Totales'!C9 -> 0 | E9: =G$1*C9 -> 0
B10: Nueces | C10: 0 | D10: =C10*'Valores y Totales'!C10 -> 0 | E10: =G$1*C10 -> 0
B11: Dulce de Leche | C11: 1200 | D11: =C11*'Valores y Totales'!C11 -> 6000 | E11: =G$1*C11 -> 1200
B12: Crema | C12: 0 | D12: =C12*'Valores y Totales'!C12 -> 0 | E12: =G$1*C12 -> 0
B13: Harina Leudante | C13: 0 | D13: =C13*'Valores y Totales'!C13 -> 0 | E13: =G$1*C13 -> 0
B14: Limon | C14: 1 | D14: =C14*'Valores y Totales'!C14 -> 500 | E14: =G$1*C14 -> 1
B15: Bicarbonato | C15: 0 | D15: =C15*'Valores y Totales'!C15 -> 0 | E15: =G$1*C15 -> 0
B16: Polveo Hornear | C16: 15 | D16: =C16*'Valores y Totales'!C16 -> 60 | E16: =G$1*C16 -> 15
B17: Leche | C17: 0 | D17: =C17*'Valores y Totales'!C17 -> 0 | E17: =G$1*C17 -> 0
B18: Conac | C18: 0 | D18: =C18*'Valores y Totales'!C18 -> 0 | E18: =G$1*C18 -> 0
... B25: Yogur | C25: 0 | D25: =C25*'Valores y Totales'!C25 -> 0 | E25: =G$1*C25 -> 0
B26: Dulce de Membrillo | C26: 0 | D26: =C26*'Valores y Totales'!C45 -> 0 | E26: =G$1*C26 -> 0
B27: Chocochips | C27: 0 | D27: =C27*'Valores y Totales'!C26 -> 0 | E27: =G$1*C27 -> 0
C29: Una Receta | D29: Por Cantidad de Recetas
B30: Cantidad de Masitas | C30: 15 | D30: =C30*G$1 -> 15 | E30: de 8 cm
B31: Costo Receta | C31: =SUM(D2:D27) -> 10505 | D31: =C31*G$1 -> 10505
B32: Costo por unidad | C32: =C31/C30 -> 700.33333 | D32: =C32 -> 700.33333
B33: Costo Individual | C33: =C31/C30 -> 700.33333 | D33: =C33 -> 700.33333

Sheet Pastafrola Membrillo
B1: Ingrediente | C1: Gramos | D1: Precio | E1: Total Recetas | F1: Cantidad de Recetas: | G1: 1
B2: Manteca | C2: 250 | D2: =C2*'Valores y Totales'!C2 -> 2750 | E2: =G$1*C2 -> 250
B3: Harina 0000 | C3: 500 | D3: =C3*'Valores y Totales'!C3 -> 550 | E3: =G$1*C3 -> 500
B4: Azucar Impalpable | C4: 150 | D4: =C4*'Valores y Totales'!C4 -> 225 | E4: =G$1*C4 -> 150
B5: Cacao | C5: 0 | D5: =C5*'Valores y Totales'!C5 -> 0 | E5: =G$1*C5 -> 0
B6: Huevo (unidad) | C6: 2 | D6: =C6*'Valores y Totales'!B6 -> 420 | E6: =G$1*C6 -> 2
B7: Azucar Común | C7: 0 | D7: =C7*'Valores y Totales'!C7 -> 0 | E7: =G$1*C7 -> 0
B8: Maizena | C8: 0 | D8: =C8*'Valores y Totales'!C8 -> 0 | E8: =G$1*C8 -> 0
B9: Chocolate Taza | C9: 0 | D9: =C9*'Valores y Totales'!C9 -> 0 | E9: =G$1*C9 -> 0
B10: Nueces | C10: 0 | D10: =C10*'Valores y Totales'!C10 -> 0 | E10: =G$1*C10 -> 0
B11: Dulce de Leche | C11: 0 | D11: =C11*'Valores y Totales'!C11 -> 0 | E11: =G$1*C11 -> 0
B12: Crema | C12: 0 | D12: =C12*'Valores y Totales'!C12 -> 0 | E12: =G$1*C12 -> 0
B13: Harina Leudante | C13: 0 | D13: =C13*'Valores y Totales'!C13 -> 0 | E13: =G$1*C13 -> 0
B14: Limon | C14: 1 | D14: =C14*'Valores y Totales'!C14 -> 500 | E14: =G$1*C14 -> 1
B15: Bicarbonato | C15: 0 | D15: =C15*'Valores y Totales'!C15 -> 0 | E15: =G$1*C15 -> 0
B16: Polveo Hornear | C16: 10 | D16: =C16*'Valores y Totales'!C16 -> 40 | E16: =G$1*C16 -> 10
B17: Leche | C17: 0 | D17: =C17*'Valores y Totales'!C17 -> 0 | E17: =G$1*C17 -> 0
B18: Conac | C18: 0 | D18: =C18*'Valores y Totales'!C18 -> 0 | E18: =G$1*C18 -> 0
... B25: Yogur | C25: 0 | D25: =C25*'Valores y Totales'!C25 -> 0 | E25: =G$1*C25 -> 0
B26: Dulce de Membrillo | C26: 1200 | D26: =C26*'Valores y Totales'!C45 -> 7200 | E26: =G$1*C26 -> 1200
B27: Chocochips | C27: 0 | D27: =C27*'Valores y Totales'!C26 -> 0 | E27: =G$1*C27 -> 0
C29: Una Receta | D29: Por Cantidad de Recetas
B30: Cantidad de Masitas | C30: 60 | D30: =C30*G$1 -> 60
B31: Costo Receta | C31: =SUM(D2:D27) -> 11685 | D31: =C31*G$1 -> 11685
B32: Costo por unidad | C32: =C31/C30 -> 194.75 | D32: =C32 -> 194.75
B33: Costo Individual | C33: =C31/C30 -> 194.75 | D33: =C33 -> 194.75

Sheet Minifrola-Membrillo
B1: Ingrediente | C1: Gramos | D1: Precio | E1: Total Recetas | F1: Cantidad de Recetas: | G1: 1
B2: Manteca | C2: 250 | D2: =C2*'Valores y Totales'!C2 -> 2750 | E2: =G$1*C2 -> 250
B3: Harina 0000 | C3: 500 | D3: =C3*'Valores y Totales'!C3 -> 550 | E3: =G$1*C3 -> 500
B4: Azucar Impalpable | C4: 150 | D4: =C4*'Valores y Totales'!C4 -> 225 | E4: =G$1*C4 -> 150
B5: Cacao | C5: 0 | D5: =C5*'Valores y Totales'!C5 -> 0 | E5: =G$1*C5 -> 0
B6: Huevo (unidad) | C6: 2 | D6: =C6*'Valores y Totales'!B6 -> 420 | E6: =G$1*C6 -> 2
B7: Azucar Común | C7: 0 | D7: =C7*'Valores y Totales'!C7 -> 0 | E7: =G$1*C7 -> 0
B8: Maizena | C8: 0 | D8: =C8*'Valores y Totales'!C8 -> 0 | E8: =G$1*C8 -> 0
B9: Chocolate Taza | C9: 0 | D9: =C9*'Valores y Totales'!C9 -> 0 | E9: =G$1*C9 -> 0
B10: Nueces | C10: 0 | D10: =C10*'Valores y Totales'!C10 -> 0 | E10: =G$1*C10 -> 0
B11: Dulce de Leche | C11: 0 | D11: =C11*'Valores y Totales'!C11 -> 0 | E11: =G$1*C11 -> 0
B12: Crema | C12: 0 | D12: =C12*'Valores y Totales'!C12 -> 0 | E12: =G$1*C12 -> 0
B13: Harina Leudante | C13: 0 | D13: =C13*'Valores y Totales'!C13 -> 0 | E13: =G$1*C13 -> 0
B14: Limon | C14: 1 | D14: =C14*'Valores y Totales'!C14 -> 500 | E14: =G$1*C14 -> 1
B15: Bicarbonato | C15: 0 | D15: =C15*'Valores y Totales'!C15 -> 0 | E15: =G$1*C15 -> 0
B16: Polveo Hornear | C16: 10 | D16: =C16*'Valores y Totales'!C16 -> 40 | E16: =G$1*C16 -> 10
B17: Leche | C17: 0 | D17: =C17*'Valores y Totales'!C17 -> 0 | E17: =G$1*C17 -> 0
B18: Conac | C18: 0 | D18: =C18*'Valores y Totales'!C18 -> 0 | E18: =G$1*C18 -> 0
... B25: Yogur | C25: 0 | D25: =C25*'Valores y Totales'!C25 -> 0 | E25: =G$1*C25 -> 0
B26: Dulce de Membrillo | C26: 1200 | D26: =C26*'Valores y Totales'!C45 -> 7200 | E26: =G$1*C26 -> 1200
B27: Chocochips | C27: 0 | D27: =C27*'Valores y Totales'!C26 -> 0 | E27: =G$1*C27 -> 0
C29: Una Receta | D29: Por Cantidad de Recetas
B30: Cantidad de Masitas | C30: 15 | D30: =C30*G$1 -> 15 | E30: de 8 cm
B31: Costo Receta | C31: =SUM(D2:D27) -> 11685 | D31: =C31*G$1 -> 11685
B32: Costo por unidad | C32: =C31/C30 -> 779 | D32: =C32 -> 779
B33: Costo Individual | C33: =C31/C30 -> 779 | D33: =C33 -> 779

Sheet Pepas
B1: Ingrediente | C1: Gramos | D1: Precio | E1: Total Recetas | F1: Cantidad de Recetas: | G1: 1
B2: Manteca | C2: 125 | D2: =C2*'Valores y Totales'!C2 -> 1375 | E2: =G$1*C2 -> 125
B3: Harina 0000 | C3: 300 | D3: =C3*'Valores y Totales'!C3 -> 330 | E3: =G$1*C3 -> 300
B4: Azucar Impalpable | C4: 0 | D4: =C4*'Valores y Totales'!C4 -> 0 | E4: =G$1*C4 -> 0
B5: Cacao | C5: 0 | D5: =C5*'Valores y Totales'!C5 -> 0 | E5: =G$1*C5 -> 0
B6: Huevo (unidad) | C6: 2 | D6: =C6*'Valores y Totales'!B6 -> 420 | E6: =G$1*C6 -> 2
B7: Azucar Común | C7: 125 | D7: =C7*'Valores y Totales'!C7 -> 175 | E7: =G$1*C7 -> 125
B8: Maizena | C8: 0 | D8: =C8*'Valores y Totales'!C8 -> 0 | E8: =G$1*C8 -> 0
B9: Chocolate Taza | C9: 0 | D9: =C9*'Valores y Totales'!C9 -> 0 | E9: =G$1*C9 -> 0
B10: Nueces | C10: 0 | D10: =C10*'Valores y Totales'!C10 -> 0 | E10: =G$1*C10 -> 0
B11: Dulce de Leche | C11: 0 | D11: =C11*'Valores y Totales'!C11 -> 0 | E11: =G$1*C11 -> 0
B12: Crema | C12: 0 | D12: =C12*'Valores y Totales'!C12 -> 0 | E12: =G$1*C12 -> 0
B13: Harina Leudante | C13: 0 | D13: =C13*'Valores y Totales'!C13 -> 0 | E13: =G$1*C13 -> 0
B14: Limon | C14: 1 | D14: =C14*'Valores y Totales'!C14 -> 500 | E14: =G$1*C14 -> 1
B15: Bicarbonato | C15: 0 | D15: =C15*'Valores y Totales'!C15 -> 0 | E15: =G$1*C15 -> 0
B16: Polveo Hornear | C16: 8 | D16: =C16*'Valores y Totales'!C16 -> 32 | E16: =G$1*C16 -> 8
B17: Leche | C17: 0 | D17: =C17*'Valores y Totales'!C17 -> 0 | E17: =G$1*C17 -> 0
B18: Conac | C18: 0 | D18: =C18*'Valores y Totales'!C18 -> 0 | E18: =G$1*C18 -> 0
... B25: Yogur | C25: 0 | D25: =C25*'Valores y Totales'!C25 -> 0 | E25: =G$1*C25 -> 0
B26: Dulce de Membrillo | C26: 300 | D26: =C26*'Valores y Totales'!C45 -> 1800 | E26: =G$1*C26 -> 300
B27: Chocochips | C27: 0 | D27: =C27*'Valores y Totales'!C26 -> 0 | E27: =G$1*C27 -> 0
C29: Una Receta | D29: Por Cantidad de Recetas
B30: Cantidad de Masitas | C30: 48 | D30: =C30*G$1 -> 48
B31: Costo Receta | C31: =SUM(D2:D27) -> 4632 | D31: =C31*G$1 -> 4632
B32: Costo Docena | C32: =C31/C30*12 -> 1158 | D32: =C32 -> 1158
B33: Costo Individual | C33: =C31/C30 -> 96.5 | D33: =C33 -> 96.5

Sheet Crema Bariloche
B1: Ingrediente | C1: Gramos | D1: Precio | E1: Total Recetas | F1: Cantidad de Recetas: | G1: 1
B2: Manteca | C2: 60 | D2: =C2*'Valores y Totales'!C2 -> 660 | E2: =G$1*C2 -> 60
B3: Harina 0000 | C3: 0 | D3: =C3*'Valores y Totales'!C3 -> 0 | E3: =G$1*C3 -> 0
B4: Azucar Impalpable | C4: 0 | D4: =C4*'Valores y Totales'!C4 -> 0 | E4: =G$1*C4 -> 0
B5: Cacao | C5: 0 | D5: =C5*'Valores y Totales'!C5 -> 0 | E5: =G$1*C5 -> 0
B6: Huevo (unidad) | C6: 0 | D6: =C6*'Valores y Totales'!B6 -> 0 | E6: =G$1*C6 -> 0
B7: Azucar Común | C7: 0 | D7: =C7*'Valores y Totales'!C7 -> 0 | E7: =G$1*C7 -> 0
B8: Maizena | C8: 0 | D8: =C8*'Valores y Totales'!C8 -> 0 | E8: =G$1*C8 -> 0
B9: Chocolate Taza | C9: 150 | D9: =C9*'Valores y Totales'!C9 -> 3900 | E9: =G$1*C9 -> 150
B10: Nueces | C10: 0 | D10: =C10*'Valores y Totales'!C10 -> 0 | E10: =G$1*C10 -> 0
B11: Dulce de Leche | C11: 400 | D11: =C11*'Valores y Totales'!C11 -> 2000 | E11: =G$1*C11 -> 400
B12: Crema | C12: 120 | D12: =C12*'Valores y Totales'!C12 -> 1200 | E12: =G$1*C12 -> 120
B13: Harina Leudante | C13: 0 | D13: =C13*'Valores y Totales'!C13 -> 0 | E13: =G$1*C13 -> 0
B14: Limon | C14: 0 | D14: =C14*'Valores y Totales'!C14 -> 0 | E14: =G$1*C14 -> 0
B15: Bicarbonato | C15: 0 | D15: =C15*'Valores y Totales'!C15 -> 0 | E15: =G$1*C15 -> 0
B16: Polveo Hornear | C16: 0 | D16: =C16*'Valores y Totales'!C16 -> 0 | E16: =G$1*C16 -> 0
B17: Leche | C17: 0 | D17: =C17*'Valores y Totales'!C17 -> 0 | E17: =G$1*C17 -> 0
B18: Conac | C18: 30 | D18: =C18*'Valores y Totales'!C18 -> 400 | E18: =G$1*C18 -> 30
... B26: Chocochips | C26: 0 | D26: =C26*'Valores y Totales'!C26 -> 0 | E26: =G$1*C26 -> 0
C28: Una Receta | D28: Por Cantidad de Recetas
B29: Cantidad de Masitas | C29: 1 | D29: =C29*G$1 -> 1
B30: Costo Receta | C30: =SUM(D2:D26) -> 8160 | D30: =C30*G$1 -> 8160
B31: Costo Docena | C31: =C30/C29*12 -> 97920 | D31: =C31 -> 97920
B32: Costo Individual | C32: =C30/C29 -> 8160 | D32: =C32 -> 8160

Sheet Receta Torta Espumita
B1: Ingrediente | C1: Gramos | D1: Precio | E1: Total Recetas | F1: Cantidad de Recetas: | G1: 1
B2: Manteca | C2: 150 | D2: =C2*'Valores y Totales'!C2 -> 1650 | E2: =G$1*C2 -> 150
B3: Harina 0000 | C3: 150 | D3: =C3*'Valores y Totales'!C3 -> 165 | E3: =G$1*C3 -> 150
B4: Azucar Impalpable | C4: 0 | D4: =C4*'Valores y Totales'!C4 -> 0 | E4: =G$1*C4 -> 0
B5: Cacao | C5: 0 | D5: =C5*'Valores y Totales'!C5 -> 0 | E5: =G$1*C5 -> 0
B6: Huevo (unidad) | C6: 3 | D6: =C6*'Valores y Totales'!B6 -> 630 | E6: =G$1*C6 -> 3
B7: Azucar Común | C7: 250 | D7: =C7*'Valores y Totales'!C7 -> 350 | E7: =G$1*C7 -> 250
B8: Maizena | C8: 100 | D8: =C8*'Valores y Totales'!C8 -> 210 | E8: =G$1*C8 -> 100
B9: Chocolate Taza | C9: 0 | D9: =C9*'Valores y Totales'!C9 -> 0 | E9: =G$1*C9 -> 0
B10: Nueces | C10: 0 | D10: =C10*'Valores y Totales'!C10 -> 0 | E10: =G$1*C10 -> 0
B11: Dulce de Leche | C11: 0 | D11: =C11*'Valores y Totales'!C11 -> 0 | E11: =G$1*C11 -> 0
B12: Crema | C12: 0 | D12: =C12*'Valores y Totales'!C12 -> 0 | E12: =G$1*C12 -> 0
B13: Harina Leudante | C13: 0 | D13: =C13*'Valores y Totales'!C13 -> 0 | E13: =G$1*C13 -> 0
B14: Limon | C14: 0 | D14: =C14*'Valores y Totales'!C14 -> 0 | E14: =G$1*C14 -> 0
B15: Bicarbonato | C15: 0 | D15: =C15*'Valores y Totales'!C15 -> 0 | E15: =G$1*C15 -> 0
B16: Polveo Hornear | C16: 20 | D16: =C16*'Valores y Totales'!C16 -> 80 | E16: =G$1*C16 -> 20
B17: Leche | C17: 100 | D17: =C17*'Valores y Totales'!C17 -> 250 | E17: =G$1*C17 -> 100
B18: Conac | C18: 0 | D18: =C18*'Valores y Totales'!C18 -> 0 | E18: =G$1*C18 -> 0
... B26: Chocochips | C26: 0 | D26: =C26*'Valores y Totales'!C26 -> 0 | E26: =G$1*C26 -> 0
C28: Una Receta | D28: Por Cantidad de Recetas
B29: Cantidad de Masitas | C29: 25 | D29: =C29*G$1 -> 25
B30: Costo Receta | C30: =SUM(D2:D20) -> 3335 | D30: =C30*G$1 -> 3335
B31: Costo Docena | C31: =C30/C29*12 -> 1600.8 | D31: =C31 -> 1600.8
B32: Costo Individual | C32: =C30/C29 -> 133.4 | D32: =C32 -> 133.4

Sheet Cupcakes Chocolate
B1: Ingrediente | C1: Gramos | D1: Precio | E1: Total Recetas | F1: Cantidad de Recetas: | G1: 1
B2: Manteca | C2: 110 | D2: =C2*'Valores y Totales'!C2 -> 1210 | E2: =G$1*C2 -> 110
B3: Harina 0000 | C3: 0 | D3: =C3*'Valores y Totales'!C3 -> 0 | E3: =G$1*C3 -> 0
B4: Azucar Impalpable | C4: 0 | D4: =C4*'Valores y Totales'!C4 -> 0 | E4: =G$1*C4 -> 0
B5: Cacao | C5: 50 | D5: =C5*'Valores y Totales'!C5 -> 1250 | E5: =G$1*C5 -> 50
B6: Huevo (unidad) | C6: 2 | D6: =C6*'Valores y Totales'!B6 -> 420 | E6: =G$1*C6 -> 2
B7: Azucar Común | C7: 0 | D7: =C7*'Valores y Totales'!C7 -> 0 | E7: =G$1*C7 -> 0
B8: Maizena | C8: 0 | D8: =C8*'Valores y Totales'!C8 -> 0 | E8: =G$1*C8 -> 0
B9: Chocolate Taza | C9: 0 | D9: =C9*'Valores y Totales'!C9 -> 0 | E9: =G$1*C9 -> 0
B10: Nueces | C10: 0 | D10: =C10*'Valores y Totales'!C10 -> 0 | E10: =G$1*C10 -> 0
B11: Dulce de Leche | C11: 0 | D11: =C11*'Valores y Totales'!C11 -> 0 | E11: =G$1*C11 -> 0
B12: Crema | C12: 0 | D12: =C12*'Valores y Totales'!C12 -> 0 | E12: =G$1*C12 -> 0
B13: Harina Leudante | C13: 250 | D13: =C13*'Valores y Totales'!C13 -> 525 | E13: =G$1*C13 -> 250
B14: Limon | C14: 0 | D14: =C14*'Valores y Totales'!C14 -> 0 | E14: =G$1*C14 -> 0
B15: Bicarbonato | C15: 0 | D15: =C15*'Valores y Totales'!C15 -> 0 | E15: =G$1*C15 -> 0
B16: Polveo Hornear | C16: 0 | D16: =C16*'Valores y Totales'!C16 -> 0 | E16: =G$1*C16 -> 0
B17: Leche | C17: 160 | D17: =C17*'Valores y Totales'!C17 -> 400 | E17: =G$1*C17 -> 160
B18: Conac | C18: 0 | D18: =C18*'Valores y Totales'!C18 -> 0 | E18: =G$1*C18 -> 0
... B31: Pasta de Forrar | C31: 0 | D31: =C31*'Valores y Totales'!C31 -> 0 | E31: =G$1*C31 -> 0
B32: PIROTINES | C32: 12 | D32: 30
C36: Una Receta | D36: Por Cantidad de Recetas
B37: Cantidad de Porciones | C37: 12 | D37: =C37*G$1 -> 12
B38: Costo Receta | C38: =SUM(D2:D32) -> 4203 | D38: =C38*G$1 -> 4203

Sheet Ganache Isabel Vermal
B1: Ingrediente | C1: Gramos | D1: Precio | E1: Total Recetas | F1: Cantidad de Recetas: | G1: 1
B2: Manteca | D2: =C2*'Valores y Totales'!C2 -> 0 | E2: =G$1*C2 -> 0
B3: Harina 0000 | D3: =C3*'Valores y Totales'!C3 -> 0 | E3: =G$1*C3 -> 0
B4: Azucar Impalpable | D4: =C4*'Valores y Totales'!C4 -> 0 | E4: =G$1*C4 -> 0
B5: Cacao | D5: =C5*'Valores y Totales'!C5 -> 0 | E5: =G$1*C5 -> 0
B6: Huevo (unidad) | D6: =C6*'Valores y Totales'!B6 -> 0 | E6: =G$1*C6 -> 0
B7: Azucar Común | D7: =C7*'Valores y Totales'!C7 -> 0 | E7: =G$1*C7 -> 0
B8: Maizena | D8: =C8*'Valores y Totales'!C8 -> 0 | E8: =G$1*C8 -> 0
B9: Chocolate Taza | C9: 270 | D9: =C9*'Valores y Totales'!C9 -> 7020 | E9: =G$1*C9 -> 270
B10: Nueces | D10: =C10*'Valores y Totales'!C10 -> 0 | E10: =G$1*C10 -> 0
B11: Dulce de Leche | C11: 250 | D11: =C11*'Valores y Totales'!C11 -> 1250 | E11: =G$1*C11 -> 250
B12: Crema | C12: 300 | D12: =C12*'Valores y Totales'!C12 -> 3000 | E12: =G$1*C12 -> 300
B13: Harina Leudante | D13: =C13*'Valores y Totales'!C13 -> 0 | E13: =G$1*C13 -> 0
B14: Limon | D14: =C14*'Valores y Totales'!C14 -> 0 | E14: =G$1*C14 -> 0
B15: Bicarbonato | D15: =C15*'Valores y Totales'!C15 -> 0 | E15: =G$1*C15 -> 0
B16: Polveo Hornear | D16: =C16*'Valores y Totales'!C16 -> 0 | E16: =G$1*C16 -> 0
B17: Leche | D17: =C17*'Valores y Totales'!C17 -> 0 | E17: =G$1*C17 -> 0
B18: Conac | D18: =C18*'Valores y Totales'!C18 -> 0 | E18: =G$1*C18 -> 0
B19: Naranja | D19: =C19*'Valores y Totales'!C19 -> 0 | E19: =G$1*C19 -> 0
B20: Azucar Negro | D20: =C20*'Valores y Totales'!C20 -> 0 | E20: =G$1*C20 -> 0
B21: Chocolate Baño | C21: 0 | D21: =C21*'Valores y Totales'!C21 -> 0 | E21: =G$1*C21 -> 0
B22: Biscochuelo | D22: =C22*'Valores y Totales'!C22 -> 0 | E22: =G$1*C22 -> 0
B23: Ciruelas | C23: 0 | D23: =C23*'Valores y Totales'!C23 -> 0 | E23: =G$1*C23 -> 0
B24: Pasas | C24: 0 | D24: 0 | E24: =G$1*C24 -> 0
B25: Yogur | C25: 0 | D25: 0 | E25: =G$1*C25 -> 0
B26: Chocochips | C26: 0 | D26: 0 | E26: =G$1*C26 -> 0
C28: Una Receta | D28: Por Cantidad de Recetas
B29: Cantidad de Porciones | C29: 1 | D29: 1
B30: Costo Receta | C30: =SUM(D2:D22) -> 11270 | D30: =C30*G$1 -> 11270
B31: Costo Docena | C31: 0 | D31: =C31 -> 0
B32: Costo Individual | C32: =C30/C29 -> 11270 | D32: =C32 -> 11270

Sheet Torta Choc Isabel Vermal
B1: Ingrediente | C1: Gramos | D1: Precio | E1: Total Recetas | F1: Cantidad de Recetas: | G1: 1
B2: Manteca | C2: 150 | D2: =C2*'Valores y Totales'!C2 -> 1650 | E2: =G$1*C2 -> 150
B3: Harina 0000 | C3: 300 | D3: =C3*'Valores y Totales'!C3 -> 330 | E3: =G$1*C3 -> 300
B4: Azucar Impalpable | C4: 0 | D4: =C4*'Valores y Totales'!C4 -> 0 | E4: =G$1*C4 -> 0
B5: Cacao | C5: 100 | D5: =C5*'Valores y Totales'!C5 -> 2500 | E5: =G$1*C5 -> 100
B6: Huevo (unidad) | C6: 3 | D6: =C6*'Valores y Totales'!B6 -> 630 | E6: =G$1*C6 -> 3
B7: Azucar Común | C7: 250 | D7: =C7*'Valores y Totales'!C7 -> 350 | E7: =G$1*C7 -> 250
B8: Maizena | C8: 0 | D8: =C8*'Valores y Totales'!C8 -> 0 | E8: =G$1*C8 -> 0
B9: Chocolate Taza | C9: 0 | D9: =C9*'Valores y Totales'!C9 -> 0 | E9: =G$1*C9 -> 0
B10: Nueces | C10: 0 | D10: =C10*'Valores y Totales'!C10 -> 0 | E10: =G$1*C10 -> 0
B11: Dulce de Leche | C11: 0 | D11: =C11*'Valores y Totales'!C11 -> 0 | E11: =G$1*C11 -> 0
B12: Crema | C12: 0 | D12: =C12*'Valores y Totales'!C12 -> 0 | E12: =G$1*C12 -> 0
B13: Harina Leudante | C13: 0 | D13: =C13*'Valores y Totales'!C13 -> 0 | E13: =G$1*C13 -> 0
B14: Limon | C14: 1 | D14: =C14*'Valores y Totales'!C14 -> 500 | E14: =G$1*C14 -> 1
B15: Bicarbonato | C15: 0 | D15: =C15*'Valores y Totales'!C15 -> 0 | E15: =G$1*C15 -> 0
B16: Polveo Hornear | C16: 0 | D16: =C16*'Valores y Totales'!C16 -> 0 | E16: =G$1*C16 -> 0
B17: Leche | C17: 270 | D17: =C17*'Valores y Totales'!C17 -> 675 | E17: =G$1*C17 -> 270
B18: Conac | C18: 0 | D18: =C18*'Valores y Totales'!C18 -> 0 | E18: =G$1*C18 -> 0
... B26: Chocochips | C26: 0 | D26: =C26*'Valores y Totales'!C26 -> 0 | E26: =G$1*C26 -> 0
C28: Una Receta | D28: Por Cantidad de Recetas
B29: Cantidad de Porciones | C29: 1 | D29: =C29*G$1 -> 1
B30: Costo Receta | C30: =SUM(D2:D20) -> 7210 | D30: 1
B31: Costo Individual | C31: =C30/C29 -> 7210 | D31: =C31 -> 7210

Sheet Biscuit Chocolate
B1: Ingrediente | C1: Gramos | D1: Precio | E1: Total Recetas | F1: Cantidad de Recetas: | G1: 1
B2: Manteca | C2: 75 | D2: =C2*'Valores y Totales'!C2 -> 825 | E2: =G$1*C2 -> 75
B3: Harina 0000 | C3: 270 | D3: =C3*'Valores y Totales'!C3 -> 297 | E3: =G$1*C3 -> 270
B4: Azucar Impalpable | C4: 0 | D4: =C4*'Valores y Totales'!C4 -> 0 | E4: =G$1*C4 -> 0
B5: Cacao | C5: 0 | D5: =C5*'Valores y Totales'!C5 -> 0 | E5: =G$1*C5 -> 0
B6: Huevo (unidad) | C6: 2 | D6: =C6*'Valores y Totales'!B6 -> 420 | E6: =G$1*C6 -> 2
B7: Azucar Común | C7: 165 | D7: =C7*'Valores y Totales'!C7 -> 231 | E7: =G$1*C7 -> 165
B8: Maizena | C8: 0 | D8: =C8*'Valores y Totales'!C8 -> 0 | E8: =G$1*C8 -> 0
B9: Chocolate Taza | C9: 170 | D9: =C9*'Valores y Totales'!C9 -> 4420 | E9: =G$1*C9 -> 170
B10: Nueces | C10: 0 | D10: =C10*'Valores y Totales'!C10 -> 0 | E10: =G$1*C10 -> 0
B11: Dulce de Leche | C11: 0 | D11: =C11*'Valores y Totales'!C11 -> 0 | E11: =G$1*C11 -> 0
B12: Crema | C12: 225 | D12: =C12*'Valores y Totales'!C12 -> 2250 | E12: =G$1*C12 -> 225
B13: Harina Leudante | C13: 0 | D13: =C13*'Valores y Totales'!C13 -> 0 | E13: =G$1*C13 -> 0
B14: Limon | C14: 0 | D14: =C14*'Valores y Totales'!C14 -> 0 | E14: =G$1*C14 -> 0
B15: Bicarbonato | C15: 0 | D15: =C15*'Valores y Totales'!C15 -> 0 | E15: =G$1*C15 -> 0
B16: Polveo Hornear | C16: 0 | D16: =C16*'Valores y Totales'!C16 -> 0 | E16: =G$1*C16 -> 0
B17: Leche | C17: 120 | D17: =C17*'Valores y Totales'!C17 -> 300 | E17: =G$1*C17 -> 120
B18: Conac | C18: 0 | D18: =C18*'Valores y Totales'!C18 -> 0 | E18: =G$1*C18 -> 0
... B26: Chocochips | C26: 0 | D26: =C26*'Valores y Totales'!C26 -> 0 | E26: =G$1*C26 -> 0
C28: Una Receta | D28: Por Cantidad de Recetas
B29: Cantidad de Porciones | C29: 1 | D29: =C29*G$1 -> 1
B30: Costo Receta | C30: =SUM(D2:D26) -> 8846.5 | D30: =C30*G$1 -> 8846.5
B32: Costo Individual | C32: =C30/C29 -> 8846.5 | D32: =C32 -> 8846.5

Sheet Butter Cream Chocolate
B1: Ingrediente | C1: Gramos | D1: Precio | E1: Total Recetas | F1: Cantidad de Recetas: | G1: 1
B2: Manteca | C2: 250 | D2: =C2*'Valores y Totales'!C2 -> 2750 | E2: =G$1*C2 -> 250
B3: Harina 0000 | C3: 0 | D3: =C3*'Valores y Totales'!C3 -> 0 | E3: =G$1*C3 -> 0
B4: Azucar Impalpable | C4: 300 | D4: =C4*'Valores y Totales'!C4 -> 450 | E4: =G$1*C4 -> 300
B5: Cacao | C5: 45 | D5: =C5*'Valores y Totales'!C5 -> 1125 | E5: =G$1*C5 -> 45
B6: Huevo (unidad) | C6: 0 | D6: =C6*'Valores y Totales'!B6 -> 0 | E6: =G$1*C6 -> 0
B7: Azucar Común | C7: 0 | D7: =C7*'Valores y Totales'!C7 -> 0 | E7: =G$1*C7 -> 0
B8: Maizena | C8: 0 | D8: =C8*'Valores y Totales'!C8 -> 0 | E8: =G$1*C8 -> 0
B9: Chocolate Taza | C9: 0 | D9: =C9*'Valores y Totales'!C9 -> 0 | E9: =G$1*C9 -> 0
B10: Nueces | C10: 0 | D10: =C10*'Valores y Totales'!C10 -> 0 | E10: =G$1*C10 -> 0
B11: Dulce de Leche | C11: 0 | D11: =C11*'Valores y Totales'!C11 -> 0 | E11: =G$1*C11 -> 0
B12: Crema | C12: 0 | D12: =C12*'Valores y Totales'!C12 -> 0 | E12: =G$1*C12 -> 0
B13: Harina Leudante | C13: 0 | D13: =C13*'Valores y Totales'!C13 -> 0 | E13: =G$1*C13 -> 0
B14: Limon | C14: 0 | D14: =C14*'Valores y Totales'!C14 -> 0 | E14: =G$1*C14 -> 0
B15: Bicarbonato | C15: 0 | D15: =C15*'Valores y Totales'!C15 -> 0 | E15: =G$1*C15 -> 0
B16: Polveo Hornear | C16: 0 | D16: =C16*'Valores y Totales'!C16 -> 0 | E16: =G$1*C16 -> 0
B17: Leche | C17: 30 | D17: =C17*'Valores y Totales'!C17 -> 75 | E17: =G$1*C17 -> 30
B18: Conac | C18: 0 | D18: =C18*'Valores y Totales'!C18 -> 0 | E18: =G$1*C18 -> 0
... B26: Chocochips | C26: 0 | D26: =C26*'Valores y Totales'!C26 -> 0 | E26: =G$1*C26 -> 0
C28: Una Receta | D28: Por Cantidad de Recetas
B29: Cantidad de Porciones | C29: 1 | D29: =C29*G$1 -> 1
B30: Costo Receta | C30: =SUM(D2:D26) -> 4400 | D30: =C30*G$1 -> 4400
B32: Costo Individual | C32: =C30/C29 -> 4400 | D32: =C32 -> 4400

Sheet Brownie Eri
B1: Ingrediente | C1: Gramos | D1: Precio | E1: Total Recetas | F1: Cantidad de Recetas: | G1: 1
B2: Manteca | C2: 200 | D2: =C2*'Valores y Totales'!C2 -> 2200 | E2: =G$1*C2 -> 200
B3: Harina 0000 | C3: 250 | D3: =C3*'Valores y Totales'!C3 -> 275 | E3: =G$1*C3 -> 250
B4: Azucar Impalpable | C4: 0 | D4: =C4*'Valores y Totales'!C4 -> 0 | E4: =G$1*C4 -> 0
B5: Cacao | C5: 30 | D5: =C5*'Valores y Totales'!C5 -> 750 | E5: =G$1*C5 -> 30
B6: Huevo (unidad) | C6: 6 | D6: =C6*'Valores y Totales'!B6 -> 1260 | E6: =G$1*C6 -> 6
B7: Azucar Común | C7: 0 | D7: =C7*'Valores y Totales'!C7 -> 0 | E7: =G$1*C7 -> 0
B8: Maizena | C8: 0 | D8: =C8*'Valores y Totales'!C8 -> 0 | E8: =G$1*C8 -> 0
B9: Chocolate Taza | C9: 100 | D9: =C9*'Valores y Totales'!C9 -> 2600 | E9: =G$1*C9 -> 100
B10: Nueces | C10: 100 | D10: =C10*'Valores y Totales'!C10 -> 2200 | E10: =G$1*C10 -> 100
B11: Dulce de Leche | C11: 0 | D11: =C11*'Valores y Totales'!C11 -> 0 | E11: =G$1*C11 -> 0
B12: Crema | C12: 0 | D12: =C12*'Valores y Totales'!C12 -> 0 | E12: =G$1*C12 -> 0
B13: Harina Leudante | C13: 0 | D13: =C13*'Valores y Totales'!C13 -> 0 | E13: =G$1*C13 -> 0
B14: Limon | C14: 0 | D14: =C14*'Valores y Totales'!C14 -> 0 | E14: =G$1*C14 -> 0
B15: Bicarbonato | C15: 0 | D15: =C15*'Valores y Totales'!C15 -> 0 | E15: =G$1*C15 -> 0
B16: Polveo Hornear | C16: 8 | D16: =C16*'Valores y Totales'!C16 -> 32 | E16: =G$1*C16 -> 8
B17: Leche | C17: 0 | D17: =C17*'Valores y Totales'!C17 -> 0 | E17: =G$1*C17 -> 0
B18: Conac | C18: 0 | D18: =C18*'Valores y Totales'!C18 -> 0 | E18: =G$1*C18 -> 0
... B26: Chocochips | C26: 0 | D26: =C26*'Valores y Totales'!C26 -> 0 | E26: =G$1*C26 -> 0
C28: Una Receta | D28: Por Cantidad de Recetas
B29: Cantidad de Alfajores | C29: 1 | D29: =C29*G$1 -> 1
B30: Costo Receta | C30: =SUM(D2:D26) -> 11490 | D30: =C30*G$1 -> 11490
B31: Costo Docena | D31: =C31 -> 0
B32: Costo Individual | C32: =C30/C29 -> 11490 | D32: =C32 -> 11490

Sheet Alfajores de Chocolate 4 cm NUT
B1: Ingrediente | C1: Gramos | D1: Precio | E1: Total Recetas | F1: Cantidad de Recetas: | G1: 1
B2: Manteca | C2: 150 | D2: =C2*'Valores y Totales'!C2 -> 1650 | E2: =G$1*C2 -> 150
B3: Harina 0000 | C3: 200 | D3: =C3*'Valores y Totales'!C3 -> 220 | E3: =G$1*C3 -> 200
B4: Azucar Impalpable | C4: 0 | D4: =C4*'Valores y Totales'!C4 -> 0 | E4: =G$1*C4 -> 0
B5: Cacao | C5: 50 | D5: =C5*'Valores y Totales'!C5 -> 1250 | E5: =G$1*C5 -> 50
B6: Huevo (unidad) | C6: 3 | D6: =C6*'Valores y Totales'!B6 -> 630 | E6: =G$1*C6 -> 3
B7: Azucar Común | C7: 0 | D7: =C7*'Valores y Totales'!C7 -> 0 | E7: =G$1*C7 -> 0
B8: Maizena | C8: 50 | D8: =C8*'Valores y Totales'!C8 -> 105 | E8: =G$1*C8 -> 50
B9: Chocolate Taza | C9: 0 | D9: =C9*'Valores y Totales'!C9 -> 0 | E9: =G$1*C9 -> 0
B10: Nueces | C10: 0 | D10: =C10*'Valores y Totales'!C10 -> 0 | E10: =G$1*C10 -> 0
B11: Dulce de Leche | C11: 0 | D11: =C11*'Valores y Totales'!C11 -> 0 | E11: =G$1*C11 -> 0
B12: Crema | C12: 0 | D12: =C12*'Valores y Totales'!C12 -> 0 | E12: =G$1*C12 -> 0
B13: Harina Leudante | C13: 0 | D13: =C13*'Valores y Totales'!C13 -> 0 | E13: =G$1*C13 -> 0
B14: Limon | C14: 0 | D14: =C14*'Valores y Totales'!C14 -> 0 | E14: =G$1*C14 -> 0
B15: Bicarbonato | C15: 0 | D15: =C15*'Valores y Totales'!C15 -> 0 | E15: =G$1*C15 -> 0
B16: Polveo Hornear | C16: 0 | D16: =C16*'Valores y Totales'!C16 -> 0 | E16: =G$1*C16 -> 0
B17: Leche | C17: 0 | D17: =C17*'Valores y Totales'!C17 -> 0 | E17: =G$1*C17 -> 0
B18: Conac | C18: 0 | D18: =C18*'Valores y Totales'!C18 -> 0 | E18: =G$1*C18 -> 0
... B24: Pasas | C24: 0 | D24: =C24*'Valores y Totales'!C24 -> 0 | E24: =G$1*C24 -> 0
B25: Nutella | C25: =11*C29 -> 440 | D25: =C25*'Valores y Totales'!C47 -> 378.4 | E25: =G$1*C25 -> 440
B26: Chocochips | C26: 0 | D26: =C26*'Valores y Totales'!C26 -> 0 | E26: =G$1*C26 -> 0
C28: Una Receta | D28: Por Cantidad de Recetas
B29: Cantidad de Alfajores | C29: 40 | D29: =C29*G$1 -> 40
B30: Costo Receta | C30: =SUM(D2:D26) -> 8463.4 | D30: =C30*G$1 -> 8463.4
B31: Costo Docena
B32: Costo Individual | C32: =C30/C29 -> 211.585 | D32: =C32 -> 211.585

Sheet Alfajores de Nuez 4 cm
B1: Ingrediente | C1: Gramos | D1: Precio | E1: Total Recetas | F1: Cantidad de Recetas: | G1: 1
B2: Manteca | C2: 200 | D2: =C2*'Valores y Totales'!C2 -> 2200 | E2: =G$1*C2 -> 200
B3: Harina 0000 | C3: 250 | D3: =C3*'Valores y Totales'!C3 -> 275 | E3: =G$1*C3 -> 250
B4: Azucar Impalpable | C4: 0 | D4: =C4*'Valores y Totales'!C4 -> 0 | E4: =G$1*C4 -> 0
B5: Cacao | C5: 0 | D5: =C5*'Valores y Totales'!C5 -> 0 | E5: =G$1*C5 -> 0
B6: Huevo (unidad) | C6: 1 | D6: =C6*'Valores y Totales'!C6 -> 210 | E6: =G$1*C6 -> 1
B7: Azucar Común | C7: 0 | D7: =C7*'Valores y Totales'!C7 -> 0 | E7: =G$1*C7 -> 0
B8: Maizena | C8: 0 | D8: =C8*'Valores y Totales'!C8 -> 0 | E8: =G$1*C8 -> 0
B9: Chocolate Taza | C9: 0 | D9: =C9*'Valores y Totales'!C9 -> 0 | E9: =G$1*C9 -> 0
B10: Nueces | C10: 300 | D10: =C10*'Valores y Totales'!C10 -> 6600 | E10: =G$1*C10 -> 300
B11: Dulce de Leche | C11: 1200 | D11: =C11*'Valores y Totales'!C11 -> 6000 | E11: =G$1*C11 -> 1200
B12: Crema | C12: 0 | D12: =C12*'Valores y Totales'!C12 -> 0 | E12: =G$1*C12 -> 0
B13: Harina Leudante | C13: 0 | D13: =C13*'Valores y Totales'!C13 -> 0 | E13: =G$1*C13 -> 0
... B26: Chocochips | C26: 0 | D26: =C26*'Valores y Totales'!C26 -> 0 | E26: =G$1*C26 -> 0
C28: Una Receta | D28: Por Cantidad de Recetas
B29: Cantidad de Masitas | C29: 65 | D29: =C29*G$1 -> 65
B30: Costo Receta | C30: =SUM(D2:D26) -> 15745 | D30: =C30*G$1 -> 15745
B31: Costo Docena | D31: =C31 -> 0
B32: Costo Individual | C32: =C30/C29 -> 242.23077 | D32: =C32 -> 242.23077

Sheet Alfajores de Chocolate 4 cm
B1: Ingrediente | C1: Gramos | D1: Precio | E1: Total Recetas | F1: Cantidad de Recetas: | G1: 1
B2: Manteca | C2: 150 | D2: =C2*'Valores y Totales'!C2 -> 1650 | E2: =G$1*C2 -> 150
B3: Harina 0000 | C3: 200 | D3: =C3*'Valores y Totales'!C3 -> 220 | E3: =G$1*C3 -> 200
B4: Azucar Impalpable | C4: 0 | D4: =C4*'Valores y Totales'!C4 -> 0 | E4: =G$1*C4 -> 0
B5: Cacao | C5: 50 | D5: =C5*'Valores y Totales'!C5 -> 1250 | E5: =G$1*C5 -> 50
B6: Huevo (unidad) | C6: 3 | D6: =C6*'Valores y Totales'!B6 -> 630 | E6: =G$1*C6 -> 3
B7: Azucar Común | C7: 0 | D7: =C7*'Valores y Totales'!C7 -> 0 | E7: =G$1*C7 -> 0
B8: Maizena | C8: 50 | D8: =C8*'Valores y Totales'!C8 -> 105 | E8: =G$1*C8 -> 50
B9: Chocolate Taza | C9: 0 | D9: =C9*'Valores y Totales'!C9 -> 0 | E9: =G$1*C9 -> 0
B10: Nueces | C10: 0 | D10: =C10*'Valores y Totales'!C10 -> 0 | E10: =G$1*C10 -> 0
B11: Dulce de Leche | C11: =20*C29 -> 800 | D11: =C11*'Valores y Totales'!C11 -> 4000 | E11: =G$1*C11 -> 800
B12: Crema | C12: 0 | D12: =C12*'Valores y Totales'!C12 -> 0 | E12: =G$1*C12 -> 0
B13: Harina Leudante | C13: 0 | D13: =C13*'Valores y Totales'!C13 -> 0 | E13: =G$1*C13 -> 0
B14: Limon | C14: 0 | D14: =C14*'Valores y Totales'!C14 -> 0 | E14: =G$1*C14 -> 0
B15: Bicarbonato | C15: 0 | D15: =C15*'Valores y Totales'!C15 -> 0 | E15: =G$1*C15 -> 0
B16: Polveo Hornear | C16: 0 | D16: =C16*'Valores y Totales'!C16 -> 0 | E16: =G$1*C16 -> 0
B17: Leche | C17: 0 | D17: =C17*'Valores y Totales'!C17 -> 0 | E17: =G$1*C17 -> 0
B18: Conac | C18: 0 | D18: =C18*'Valores y Totales'!C18 -> 0 | E18: =G$1*C18 -> 0
B19: Naranja | C19: 0 | D19: =C19*'Valores y Totales'!C19 -> 0 | E19: =G$1*C19 -> 0
B20: Azucar Negro | C20: 100 | D20: =C20*'Valores y Totales'!C20 -> 230 | E20: =G$1*C20 -> 100
B21: Chocolate Banio | C21: 400 | D21: =C21*'Valores y Totales'!C21 -> 4000 | E21: =G$1*C21 -> 400
B22: Biscochuelo | C22: 0 | D22: =C22*'Valores y Totales'!C22 -> 0 | E22: =G$1*C22 -> 0
B23: Ciruelas | C23: 0 | D23: =C23*'Valores y Totales'!C23 -> 0 | E23: =G$1*C23 -> 0
... B26: Chocochips | C26: 0 | D26: =C26*'Valores y Totales'!C26 -> 0 | E26: =G$1*C26 -> 0
C28: Una Receta | D28: Por Cantidad de Recetas
B29: Cantidad de Alfajores | C29: 40 | D29: =C29*G$1 -> 40
B30: Costo Receta | C30: =SUM(D2:D26) -> 12085 | D30: =C30*G$1 -> 12085
B31: Costo Docena
B32: Costo Individual | C32: =C30/C29 -> 302.125 | D32: =C32 -> 302.125

Sheet Alfajores de Maicena 4 cm
B1: Ingrediente | C1: Gramos | D1: Precio | E1: Total Recetas | F1: Cantidad de Recetas: | G1: 1
B2: Manteca | C2: 200 | D2: =C2*'Valores y Totales'!C2 -> 2200 | E2: =G$1*C2 -> 200
B3: Coco | C3: 125 | D3: =C3*'Valores y Totales'!C44 -> 1500
B4: Harina 0000 | C4: 200 | D4: =C4*'Valores y Totales'!C3 -> 220 | E4: =G$1*C4 -> 200
B5: Azucar Impalpable | C5: 0 | D5: =C5*'Valores y Totales'!C4 -> 0 | E5: =G$1*C5 -> 0
B6: Cacao | C6: 0 | D6: =C6*'Valores y Totales'!C5 -> 0 | E6: =G$1*C6 -> 0
B7: Huevo (unidad) | C7: 2 | D7: =C7*'Valores y Totales'!B6 -> 420 | E7: =G$1*C7 -> 2
B8: Azucar Común | C8: 150 | D8: =C8*'Valores y Totales'!C7 -> 210 | E8: =G$1*C8 -> 150
B9: Maizena | C9: 300 | D9: =C9*'Valores y Totales'!C8 -> 630 | E9: =G$1*C9 -> 300
B10: Chocolate Taza | C10: 0 | D10: =C10*'Valores y Totales'!C9 -> 0 | E10: =G$1*C10 -> 0
B11: Nueces | C11: 0 | D11: =C11*'Valores y Totales'!C10 -> 0 | E11: =G$1*C11 -> 0
B12: Dulce de Leche | C12: 1300 | D12: =C12*'Valores y Totales'!C11 -> 6500 | E12: =G$1*C12 -> 1300
B13: Crema | C13: 0 | D13: =C13*'Valores y Totales'!C12 -> 0 | E13: =G$1*C13 -> 0
B14: Harina Leudante | C14: 0 | D14: =C14*'Valores y Totales'!C13 -> 0 | E14: =G$1*C14 -> 0
B15: Limon | C15: 1 | D15: =C15*'Valores y Totales'!C14 -> 500 | E15: =G$1*C15 -> 1
B16: Bicarbonato | C16: 0 | D16: =C16*'Valores y Totales'!C15 -> 0 | E16: =G$1*C16 -> 0
B17: Polveo Hornear | C17: 10 | D17: =C17*'Valores y Totales'!C16 -> 40 | E17: =G$1*C17 -> 10
B18: Leche | C18: 0 | D18: =C18*'Valores y Totales'!C17 -> 0 | E18: =G$1*C18 -> 0
B19: Conac | C19: 20 | D19: =C19*'Valores y Totales'!C18 -> 266.66667 | E19: =G$1*C19 -> 20
... B27: Chocochips | C27: 0 | D27: =C27*'Valores y Totales'!C26 -> 0 | E27: =G$1*C27 -> 0
C29: Una Receta | D29: Por Cantidad de Recetas
B30: Cantidad de Masitas | C30: 70 | D30: =C30*G$1 -> 70
B31: Costo Receta | C31: =SUM(D2:D27) -> 12486.667 | D31: =C31*G$1 -> 12486.667
B32: Costo Docena | D32: =C32 -> 0
B33: Costo Individual | C33: =C31/C30 -> 178.38095 | D33: =C33 -> 178.38095

Sheet Alfajores de Maicena 7 cm
B1: Ingrediente | C1: Gramos | D1: Precio | E1: Total Recetas | F1: Cantidad de Recetas: | G1: 1
B2: Manteca | C2: 200 | D2: =C2*'Valores y Totales'!C2 -> 2200 | E2: =G$1*C2 -> 200
B3: Coco | C3: 125 | D3: =C3*'Valores y Totales'!C44 -> 1500
B4: Harina 0000 | C4: 200 | D4: =C4*'Valores y Totales'!C3 -> 220 | E4: =G$1*C4 -> 200
B5: Azucar Impalpable | C5: 0 | D5: =C5*'Valores y Totales'!C4 -> 0 | E5: =G$1*C5 -> 0
B6: Cacao | C6: 0 | D6: =C6*'Valores y Totales'!C5 -> 0 | E6: =G$1*C6 -> 0
B7: Huevo (unidad) | C7: 2 | D7: =C7*'Valores y Totales'!B6 -> 420 | E7: =G$1*C7 -> 2
B8: Azucar Común | C8: 150 | D8: =C8*'Valores y Totales'!C7 -> 210 | E8: =G$1*C8 -> 150
B9: Maizena | C9: 300 | D9: =C9*'Valores y Totales'!C8 -> 630 | E9: =G$1*C9 -> 300
B10: Chocolate Taza | C10: 0 | D10: =C10*'Valores y Totales'!C9 -> 0 | E10: =G$1*C10 -> 0
B11: Nueces | C11: 0 | D11: =C11*'Valores y Totales'!C10 -> 0 | E11: =G$1*C11 -> 0
B12: Dulce de Leche | C12: 1250 | D12: =C12*'Valores y Totales'!C11 -> 6250 | E12: =G$1*C12 -> 1250
B13: Crema | C13: 0 | D13: =C13*'Valores y Totales'!C12 -> 0 | E13: =G$1*C13 -> 0
B14: Harina Leudante | C14: 0 | D14: =C14*'Valores y Totales'!C13 -> 0 | E14: =G$1*C14 -> 0
B15: Limon | C15: 1 | D15: =C15*'Valores y Totales'!C14 -> 500 | E15: =G$1*C15 -> 1
B16: Bicarbonato | C16: 0 | D16: =C16*'Valores y Totales'!C15 -> 0 | E16: =G$1*C16 -> 0
B17: Polveo Hornear | C17: 10 | D17: =C17*'Valores y Totales'!C16 -> 40 | E17: =G$1*C17 -> 10
B18: Leche | C18: 0 | D18: =C18*'Valores y Totales'!C17 -> 0 | E18: =G$1*C18 -> 0
B19: Conac | C19: 20 | D19: =C19*'Valores y Totales'!C18 -> 266.66667 | E19: =G$1*C19 -> 20
... B27: Chocochips | C27: 0 | D27: =C27*'Valores y Totales'!C26 -> 0 | E27: =G$1*C27 -> 0
C29: Una Receta | D29: Por Cantidad de Recetas
B30: Cantidad de Masitas | C30: 25 | D30: =C30*G$1 -> 25
B31: Costo Receta | C31: =SUM(D2:D27) -> 12236.667 | D31: =C31*G$1 -> 12236.667
B32: Costo Docena | D32: =C32 -> 0
B33: Costo Individual | C33: =C31/C30 -> 489.46667 | D33: =C33 -> 489.46667

Sheet Alfajores de Chocolate 7 cm
B1: Ingrediente | C1: Gramos | D1: Precio | E1: Total Recetas | F1: Cantidad de Recetas: | G1: 1
B2: Manteca | C2: 150 | D2: =C2*'Valores y Totales'!C2 -> 1650 | E2: =G$1*C2 -> 150
B3: Harina 0000 | C3: 200 | D3: =C3*'Valores y Totales'!C3 -> 220 | E3: =G$1*C3 -> 200
B4: Azucar Impalpable | C4: 0 | D4: =C4*'Valores y Totales'!C4 -> 0 | E4: =G$1*C4 -> 0
B5: Cacao | C5: 50 | D5: =C5*'Valores y Totales'!C5 -> 1250 | E5: =G$1*C5 -> 50
B6: Huevo (unidad) | C6: 3 | D6: =C6*'Valores y Totales'!B6 -> 630 | E6: =G$1*C6 -> 3
B7: Azucar Común | C7: 0 | D7: =C7*'Valores y Totales'!C7 -> 0 | E7: =G$1*C7 -> 0
B8: Maizena | C8: 50 | D8: =C8*'Valores y Totales'!C8 -> 105 | E8: =G$1*C8 -> 50
B9: Chocolate Taza | C9: 0 | D9: =C9*'Valores y Totales'!C9 -> 0 | E9: =G$1*C9 -> 0
B10: Nueces | C10: 0 | D10: =C10*'Valores y Totales'!C10 -> 0 | E10: =G$1*C10 -> 0
B11: Dulce de Leche | C11: 750 | D11: =C11*'Valores y Totales'!C11 -> 3750 | E11: =G$1*C11 -> 750
B12: Crema | C12: 0 | D12: =C12*'Valores y Totales'!C12 -> 0 | E12: =G$1*C12 -> 0
B13: Harina Leudante | C13: 0 | D13: =C13*'Valores y Totales'!C13 -> 0 | E13: =G$1*C13 -> 0
B14: Limon | C14: 0 | D14: =C14*'Valores y Totales'!C14 -> 0 | E14: =G$1*C14 -> 0
B15: Bicarbonato | C15: 0 | D15: =C15*'Valores y Totales'!C15 -> 0 | E15: =G$1*C15 -> 0
B16: Polveo Hornear | C16: 0 | D16: =C16*'Valores y Totales'!C16 -> 0 | E16: =G$1*C16 -> 0
B17: Leche | C17: 0 | D17: =C17*'Valores y Totales'!C17 -> 0 | E17: =G$1*C17 -> 0
B18: Conac | C18: 0 | D18: =C18*'Valores y Totales'!C18 -> 0 | E18: =G$1*C18 -> 0
... B26: Chocochips | C26: 0 | D26: =C26*'Valores y Totales'!C26 -> 0 | E26: =G$1*C26 -> 0
C28: Una Receta | D28: Por Cantidad de Recetas
B29: Cantidad de Alfajores | C29: 15 | D29: =C29*G$1 -> 15
B30: Costo Receta | C30: =SUM(D2:D26) -> 11835 | D30: =C30*G$1 -> 11835
B31: Costo Docena
B32: Costo Individual | C32: =C30/C29 -> 789 | D32: =C32 -> 789 | F32: =C32*2 -> 1578

Sheet Masitas Mantecosas de Choco
B1: Ingrediente | C1: Gramos | D1: Precio | E1: Total Recetas | F1: Cantidad de Recetas: | G1: 1
B2: Manteca | C2: 250 | D2: 80 | E2: =G$1*C2 -> 250
B3: Harina 0000 | C3: 315 | D3: 17.325 | E3: =G$1*C3 -> 315
B4: Azucar Impalpable | C4: 60 | D4: 4.68 | E4: =G$1*C4 -> 60
B5: Cacao | C5: 20 | D5: 21.2 | E5: =G$1*C5 -> 20
B6: Huevo (unidad) | C6: 1 | D6: 8.5 | E6: =G$1*C6 -> 1
B7: Azucar Común | C7: 0 | D7: 0 | E7: =G$1*C7 -> 0
B8: Maizena | C8: 0 | D8: 0 | E8: =G$1*C8 -> 0
B9: Chocolate Taza | C9: 0 | D9: 0 | E9: =G$1*C9 -> 0
B10: Nueces | C10: 0 | D10: 0 | E10: =G$1*C10 -> 0
B11: Dulce de Leche | C11: 0 | D11: 0 | E11: =G$1*C11 -> 0
B12: Crema | C12: 0 | D12: 0 | E12: =G$1*C12 -> 0
B13: Harina Leudante | C13: 0 | D13: 0 | E13: =G$1*C13 -> 0
... B26: Chocochips | C26: 0 | D26: 0 | E26: =G$1*C26 -> 0
C28: Una Receta | D28: Por Cantidad de Recetas
B29: Cantidad de Masitas | C29: 40 | D29: =C29*G$1 -> 40
B30: Costo Receta | C30: =SUM(D2:D26) -> 140.595 | D30: =C30*G$1 -> 140.595
B31: Costo Docena | C31: =C30/C29*12 -> 42.1785 | D31: =C31 -> 42.1785
B32: Costo Individual | C32: =C30/C29 -> 3.514875 | D32: =C32 -> 3.514875

Sheet Galletas Naranja Manga
B1: Ingrediente | C1: Gramos | D1: Precio | E1: Total Recetas | F1: Cantidad de Recetas: | G1: 1
B2: Manteca | C2: 100 | D2: 32 | E2: =G$1*C2 -> 100
B3: Harina 0000 | C3: 150 | D3: 8.25 | E3: =G$1*C3 -> 150
B4: Azucar Impalpable | C4: 75 | D4: 5.85 | E4: =G$1*C4 -> 75
B5: Cacao | C5: 0 | D5: 0 | E5: =G$1*C5 -> 0
B6: Huevo (unidad) | C6: 2 | D6: 17 | E6: =G$1*C6 -> 2
B7: Azucar Común | C7: 0 | D7: 0 | E7: =G$1*C7 -> 0
B8: Maizena | C8: 0 | D8: 0 | E8: =G$1*C8 -> 0
B9: Chocolate Taza | C9: 0 | D9: 0 | E9: =G$1*C9 -> 0
B10: Nueces | C10: 0 | D10: 0 | E10: =G$1*C10 -> 0
B11: Dulce de Leche | C11: 0 | D11: 0 | E11: =G$1*C11 -> 0
B12: Crema | C12: 0 | D12: 0 | E12: =G$1*C12 -> 0
B13: Harina Leudante | C13: 0 | D13: 0 | E13: =G$1*C13 -> 0
... B26: Chocochips | C26: 0 | D26: 0 | E26: =G$1*C26 -> 0
C28: Una Receta | D28: Por Cantidad de Recetas
B29: Cantidad de Masitas | C29: 40 | D29: =C29*G$1 -> 40
B30: Costo Receta | C30: =SUM(D2:D26) -> 73.1 | D30: =C30*G$1 -> 73.1
B31: Costo Docena | C31: =C30/C29*12 -> 21.93 | D31: =C31 -> 21.93
B32: Costo Individual | C32: =C30/C29 -> 1.8275 | D32: =C32 -> 1.8275

Sheet Cookies Ginger Snaps
B1: Ingrediente | C1: Gramos | D1: Precio | E1: Total Recetas | F1: Cantidad de Recetas: | G1: 1
B2: Manteca | C2: 180 | D2: =C2*'Valores y Totales'!C2 -> 1980 | E2: =G$1*C2 -> 180
B3: Harina 0000 | C3: 500 | D3: =C3*'Valores y Totales'!C3 -> 550 | E3: =G$1*C3 -> 500
B4: Azucar Impalpable | C4: 0 | D4: =C4*'Valores y Totales'!C4 -> 0 | E4: =G$1*C4 -> 0
B5: Cacao | C5: 0 | D5: =C5*'Valores y Totales'!C5 -> 0 | E5: =G$1*C5 -> 0
B6: Huevo (unidad) | C6: 1 | D6: =C6*'Valores y Totales'!B6 -> 210 | E6: =G$1*C6 -> 1
B7: Azucar Común | C7: 300 | D7: =C7*'Valores y Totales'!C7 -> 420 | E7: =G$1*C7 -> 300
B8: Maizena | C8: 0 | D8: =C8*'Valores y Totales'!C8 -> 0 | E8: =G$1*C8 -> 0
B9: Chocolate Taza | C9: 0 | D9: =C9*'Valores y Totales'!C9 -> 0 | E9: =G$1*C9 -> 0
B10: Nueces | C10: 0 | D10: =C10*'Valores y Totales'!C10 -> 0 | E10: =G$1*C10 -> 0
B11: Dulce de Leche | C11: 0 | D11: =C11*'Valores y Totales'!C11 -> 0 | E11: =G$1*C11 -> 0
B12: Crema | C12: 0 | D12: =C12*'Valores y Totales'!C12 -> 0 | E12: =G$1*C12 -> 0
B13: Harina Leudante | C13: 0 | D13: =C13*'Valores y Totales'!C13 -> 0 | E13: =G$1*C13 -> 0
B14: Limon | C14: 0 | D14: =C14*'Valores y Totales'!C14 -> 0 | E14: =G$1*C14 -> 0
B15: Bicarbonato | C15: 2 | D15: =C15*'Valores y Totales'!C15 -> 1.8 | E15: =G$1*C15 -> 2
B16: Polveo Hornear | C16: 0 | D16: =C16*'Valores y Totales'!C16 -> 0 | E16: =G$1*C16 -> 0
B17: Leche | C17: 0 | D17: =C17*'Valores y Totales'!C17 -> 0 | E17: =G$1*C17 -> 0
B18: Conac | C18: 0 | D18: =C18*'Valores y Totales'!C18 -> 0 | E18: =G$1*C18 -> 0
... B26: Chocochips | C26: 0 | D26: =C26*'Valores y Totales'!C26 -> 0 | E26: =G$1*C26 -> 0
B27: Chips Cobertura | C27: 0 | D27: =C27*'Valores y Totales'!#REF! -> #REF! | E27: =G$1*C27 -> 0
B28: Miel | C28: 20 | D28: ='Valores y Totales'!C52*C28 -> 160 | E28: =G$1*C28 -> 20
C29: Una Receta | D29: Por Cantidad de Recetas
B30: Cantidad de Porciones | C30: 60 | D30: =C30*G$1 -> 60
B31: Costo Receta | C31: =SUM(D2:D28) -> #REF! | D31: =C31*G$1 -> #REF!
B32: Costo Docena | C32: =C31/C30*12 -> #REF! | D32: =C32 -> #REF!
B33: Costo Individual | C33: =C31/C30 -> #REF! | D33: =C33 -> #REF!
B34: Las masitas son de 5 cm de diámetro

Sheet Browkies - Cookies doble choco
B1: Ingrediente | C1: Gramos | D1: Precio | E1: Total Recetas | F1: Cantidad de Recetas: | G1: 1
B2: Manteca | C2: 110 | D2: =C2*'Valores y Totales'!C2 -> 1210 | E2: =G$1*C2 -> 110
B3: Harina 0000 | C3: 155 | D3: =C3*'Valores y Totales'!C3 -> 170.5 | E3: =G$1*C3 -> 155
B4: Azucar Impalpable | C4: 0 | D4: =C4*'Valores y Totales'!C4 -> 0 | E4: =G$1*C4 -> 0
B5: Cacao | C5: 50 | D5: =C5*'Valores y Totales'!C5 -> 1250 | E5: =G$1*C5 -> 50
B6: Huevo (unidad) | C6: 2 | D6: =C6*'Valores y Totales'!B6 -> 420 | E6: =G$1*C6 -> 2
B7: Azucar Común | C7: 0 | D7: =C7*'Valores y Totales'!C7 -> 0 | E7: =G$1*C7 -> 0
B8: Maizena | C8: 0 | D8: =C8*'Valores y Totales'!C8 -> 0 | E8: =G$1*C8 -> 0
B9: Chocolate Taza | C9: 225 | D9: =C9*'Valores y Totales'!C9 -> 5850 | E9: =G$1*C9 -> 225
B10: Nueces | C10: 0 | D10: =C10*'Valores y Totales'!C10 -> 0 | E10: =G$1*C10 -> 0
B11: Dulce de Leche | C11: 0 | D11: =C11*'Valores y Totales'!C11 -> 0 | E11: =G$1*C11 -> 0
B12: Crema | C12: 0 | D12: =C12*'Valores y Totales'!C12 -> 0 | E12: =G$1*C12 -> 0
B13: Harina Leudante | C13: 0 | D13: =C13*'Valores y Totales'!C13 -> 0 | E13: =G$1*C13 -> 0
B14: Limon | C14: 0 | D14: =C14*'Valores y Totales'!C14 -> 0 | E14: =G$1*C14 -> 0
B15: Bicarbonato | C15: 0 | D15: =C15*'Valores y Totales'!C15 -> 0 | E15: =G$1*C15 -> 0
B16: Polveo Hornear | C16: 10 | D16: =C16*'Valores y Totales'!C16 -> 40 | E16: =G$1*C16 -> 10
B17: Leche | C17: 0 | D17: =C17*'Valores y Totales'!C17 -> 0 | E17: =G$1*C17 -> 0
B18: Conac | C18: 0 | D18: =C18*'Valores y Totales'!C18 -> 0 | E18: =G$1*C18 -> 0
... B26: Chocochips | C26: 150 | D26: =C26*'Valores y Totales'!C26 -> 1200 | E26: =G$1*C26 -> 150
C27: Una Receta | D27: Por Cantidad de Recetas
B28: Cantidad de Porciones | C28: 34 | D28: =C28*G$1 -> 34
B29: Costo Receta | C29: =SUM(D2:D26) -> 10658 | D29: =C29*G$1 -> 10658
B30: Costo Docena | C30: =C29/C28*12 -> 3761.6471 | D30: =C30 -> 3761.6471
B31: Costo Individual | C31: =C29/C28 -> 313.47059 | D31: =C31 -> 313.47059
B32: Las masitas son de 5 cm de diámetro y 30 g

Sheet Cookies Chip Taller
B1: Ingrediente | C1: Gramos | D1: Precio | E1: Total Recetas | F1: Cantidad de Recetas: | G1: 1
B2: Manteca | C2: 115 | D2: =C2*'Valores y Totales'!C2 -> 1265 | E2: =G$1*C2 -> 115
B3: Harina 0000 | C3: 185 | D3: =C3*'Valores y Totales'!C3 -> 203.5 | E3: =G$1*C3 -> 185
B4: Azucar Impalpable | C4: 0 | D4: =C4*'Valores y Totales'!C4 -> 0 | E4: =G$1*C4 -> 0
B5: Cacao | C5: 0 | D5: =C5*'Valores y Totales'!C5 -> 0 | E5: =G$1*C5 -> 0
B6: Huevo (unidad) | C6: 1 | D6: =C6*'Valores y Totales'!B6 -> 210 | E6: =G$1*C6 -> 1
B7: Azucar Común | C7: 100 | D7: =C7*'Valores y Totales'!C7 -> 140 | E7: =G$1*C7 -> 100
B8: Maizena | C8: 30 | D8: =C8*'Valores y Totales'!C8 -> 63 | E8: =G$1*C8 -> 30
B9: Chocolate Taza | C9: 0 | D9: =C9*'Valores y Totales'!C9 -> 0 | E9: =G$1*C9 -> 0
B10: Nueces | C10: 0 | D10: =C10*'Valores y Totales'!C10 -> 0 | E10: =G$1*C10 -> 0
B11: Dulce de Leche | C11: 0 | D11: =C11*'Valores y Totales'!C11 -> 0 | E11: =G$1*C11 -> 0
B12: Crema | C12: 0 | D12: =C12*'Valores y Totales'!C12 -> 0 | E12: =G$1*C12 -> 0
B13: Harina Leudante | C13: 0 | D13: =C13*'Valores y Totales'!C13 -> 0 | E13: =G$1*C13 -> 0
B14: Limon | C14: 0 | D14: =C14*'Valores y Totales'!C14 -> 0 | E14: =G$1*C14 -> 0
B15: Bicarbonato | C15: 0 | D15: =C15*'Valores y Totales'!C15 -> 0 | E15: =G$1*C15 -> 0
B16: Polveo Hornear | C16: 0 | D16: =C16*'Valores y Totales'!C16 -> 0 | E16: =G$1*C16 -> 0
B17: Leche | C17: 0 | D17: =C17*'Valores y Totales'!C17 -> 0 | E17: =G$1*C17 -> 0
B18: Conac | C18: 0 | D18: =C18*'Valores y Totales'!C18 -> 0 | E18: =G$1*C18 -> 0
... B26: Chocochips | C26: 150 | D26: =C26*'Valores y Totales'!C26 -> 1200 | E26: =G$1*C26 -> 150
C28: Una Receta | D28: Por Cantidad de Recetas
B29: Cantidad de Porciones | C29: 24 | D29: =C29*G$1 -> 24
B30: Costo Receta | C30: =SUM(D2:D27) -> 3311.5 | D30: =C30*G$1 -> 3311.5
B31: Costo Docena | C31: =C30/C29*12 -> 1655.75 | D31: =C31 -> 1655.75
B32: Costo Individual | C32: =C30/C29 -> 137.97917 | D32: =C32 -> 137.97917
B33: Las masitas son de 5 cm de diámetro y 30 g

Sheet Cookies Vainilla con Chips
B1: Ingrediente | C1: Gramos | D1: Precio | E1: Total Recetas | F1: Cantidad de Recetas: | G1: 1
B2: Manteca | C2: 200 | D2: =C2*'Valores y Totales'!C2 -> 2200 | E2: =G$1*C2 -> 200
B3: Harina 0000 | C3: 450 | D3: =C3*'Valores y Totales'!C3 -> 495 | E3: =G$1*C3 -> 450
B4: Azucar Impalpable | C4: 0 | D4: =C4*'Valores y Totales'!C4 -> 0 | E4: =G$1*C4 -> 0
B5: Cacao | C5: 0 | D5: =C5*'Valores y Totales'!C5 -> 0 | E5: =G$1*C5 -> 0
B6: Huevo (unidad) | C6: 2 | D6: =C6*'Valores y Totales'!B6 -> 420 | E6: =G$1*C6 -> 2
B7: Azucar Común | C7: 400 | D7: =C7*'Valores y Totales'!C7 -> 560 | E7: =G$1*C7 -> 400
B8: Maizena | C8: 0 | D8: =C8*'Valores y Totales'!C8 -> 0 | E8: =G$1*C8 -> 0
B9: Chocolate Taza | C9: 0 | D9: =C9*'Valores y Totales'!C9 -> 0 | E9: =G$1*C9 -> 0
B10: Nueces | C10: 0 | D10: =C10*'Valores y Totales'!C10 -> 0 | E10: =G$1*C10 -> 0
B11: Dulce de Leche | C11: 0 | D11: =C11*'Valores y Totales'!C11 -> 0 | E11: =G$1*C11 -> 0
B12: Crema | C12: 0 | D12: =C12*'Valores y Totales'!C12 -> 0 | E12: =G$1*C12 -> 0
B13: Harina Leudante | C13: 0 | D13: =C13*'Valores y Totales'!C13 -> 0 | E13: =G$1*C13 -> 0
B14: Limon | C14: 0 | D14: =C14*'Valores y Totales'!C14 -> 0 | E14: =G$1*C14 -> 0
B15: Bicarbonato | C15: 0 | D15: =C15*'Valores y Totales'!C15 -> 0 | E15: =G$1*C15 -> 0
B16: Polveo Hornear | C16: 15 | D16: =C16*'Valores y Totales'!C16 -> 60 | E16: =G$1*C16 -> 15
B17: Leche | C17: 0 | D17: =C17*'Valores y Totales'!C17 -> 0 | E17: =G$1*C17 -> 0
B18: Conac | C18: 0 | D18: =C18*'Valores y Totales'!C18 -> 0 | E18: =G$1*C18 -> 0
... B26: Chocochips | C26: 150 | D26: =C26*'Valores y Totales'!C26 -> 1200 | E26: =G$1*C26 -> 150
B27: Chips Cobertura | C27: 0 | D27: =C27*'Valores y Totales'!#REF! -> #REF! | E27: =G$1*C27 -> 0
C28: Una Receta | D28: Por Cantidad de Recetas
B29: Cantidad de Porciones | C29: 66 | D29: =C29*G$1 -> 66
B30: Costo Receta | C30: =SUM(D2:D27) -> #REF! | D30: =C30*G$1 -> #REF!
B31: Costo Docena | C31: =C30/C29*12 -> #REF! | D31: =C31 -> #REF!
B32: Costo Individual | C32: =C30/C29 -> #REF! | D32: =C32 -> #REF!
B33: Las masitas son de 5 cm de diámetro

Sheet Budin de Vainilla
B1: Ingrediente | C1: Gramos | D1: Precio | E1: Total Recetas | F1: Cantidad de Recetas: | G1: 1
B2: Manteca | C2: 250 | D2: =C2*'Valores y Totales'!C2 -> 2750 | E2: =G$1*C2 -> 250
B3: Harina 0000 | C3: 0 | D3: =C3*'Valores y Totales'!C3 -> 0 | E3: =G$1*C3 -> 0 | H3: Una Receta | I3: Por Cantidad de Recetas
B4: Azucar Impalpable | C4: 0 | D4: =C4*'Valores y Totales'!C4 -> 0 | E4: =G$1*C4 -> 0 | G4: Cantidad de Porciones | H4: 1 | I4: =H4*G$1 -> 1
B5: Cacao | C5: 0 | D5: =C5*'Valores y Totales'!C5 -> 0 | E5: =G$1*C5 -> 0 | G5: Costo Receta | H5: =SUM(D2:D30) -> 12963 | I5: =H5*G$1 -> 12963
B6: Huevo (unidad) | C6: 4 | D6: =C6*'Valores y Totales'!B6 -> 840 | E6: =G$1*C6 -> 4 | G6: Costo Docena | I6: =H6 -> 0
B7: Azucar Común | C7: 250 | D7: =C7*'Valores y Totales'!C7 -> 350 | E7: =G$1*C7 -> 250 | G7: Costo Individual | H7: =H5/H4 -> 12963 | I7: =H7 -> 12963
B8: Maizena | C8: 0 | D8: =C8*'Valores y Totales'!C8 -> 0 | E8: =G$1*C8 -> 0
B9: Chocolate Taza | C9: 0 | D9: =C9*'Valores y Totales'!C9 -> 0 | E9: =G$1*C9 -> 0
B10: Nueces | C10: 0 | D10: =C10*'Valores y Totales'!C10 -> 0 | E10: =G$1*C10 -> 0 | K10: 130 | L10: 1500
B11: Dulce de Leche | C11: 0 | D11: =C11*'Valores y Totales'!C11 -> 0 | E11: =G$1*C11 -> 0 | K11: =L11*K10/L10 -> 8.6666667 | L11: 100
B12: Crema | C12: 0 | D12: =C12*'Valores y Totales'!C12 -> 0 | E12: =G$1*C12 -> 0
B13: Harina Leudante | C13: 500 | D13: =C13*'Valores y Totales'!C13 -> 1050 | E13: =G$1*C13 -> 500
B14: Limon | C14: 0 | D14: =C14*'Valores y Totales'!C14 -> 0 | E14: =G$1*C14 -> 0
B15: Bicarbonato | C15: 0 | D15: =C15*'Valores y Totales'!C15 -> 0 | E15: =G$1*C15 -> 0
B16: Polveo Hornear | C16: 0 | D16: =C16*'Valores y Totales'!C16 -> 0 | E16: =G$1*C16 -> 0
B17: Leche | C17: 160 | D17: =C17*'Valores y Totales'!C17 -> 400 | E17: =G$1*C17 -> 160
B18: Conac | C18: 0 | D18: =C18*'Valores y Totales'!C18 -> 0 | E18: =G$1*C18 -> 0
B19: Naranja | C19: 0 | D19: =C19*'Valores y Totales'!C19 -> 0 | E19: =G$1*C19 -> 0
B20: Azucar Negro | C20: 0 | D20: =C20*'Valores y Totales'!C20 -> 0 | E20: =G$1*C20 -> 0
B21: Chocolate Baño | C21: 100 | D21: =C21*'Valores y Totales'!C21 -> 1000 | E21: =G$1*C21 -> 100
B22: Biscochuelo | C22: 0 | D22: =C22*'Valores y Totales'!C22 -> 0 | E22: =G$1*C22 -> 0
B23: Ciruelas | C23: 0 | D23: =C23*'Valores y Totales'!C23 -> 0 | E23: =G$1*C23 -> 0
